<robot name="yurtbot">

  <material name="white">
    <color rgba="1 1 1 1"/>
  </material>

  <material name="blue">
    <color rgba="0 0 0.8 1"/>
  </material>

  <link name="base_link">
    <visual>
      <geometry>
        <mesh filename="package://urdf_tutorial/meshes/body_v1.STL"/>
      </geometry>
      <origin rpy="1.57075 0 0" xyz="0 0 0"/>
      <material name="white"/>
    </visual>
    <collision>
      <geometry>
        <mesh filename="package://urdf_tutorial/meshes/body_v1.STL"/>
      </geometry>
      <origin rpy="1.57075 0 0" xyz="0 0 0"/>
    </collision>
    <inertial>
    	<mass value="5"/>
    	<inertia ixx="0.4" ixy="0.0" ixz="0.0" iyy="0.4" iyz="0.0" izz="0.2"/>
    </inertial>
  </link>
  
  <joint name="prop_joint1" type="continuous">
    <parent link="base_link"/>
    <child link="prop1"/>
    <origin xyz="-0.12713 -0.07122 -0.05281" rpy="0 0 0" />
    <axis xyz="0 1 0" />
  </joint>

  <link name="prop1">
    <visual>
      <geometry>
        <mesh filename="package://urdf_tutorial/meshes/prop_m_v1.STL"/>
      </geometry>
      <origin rpy="1.57075 0 0" xyz="0 0 0"/>
      <material name="blue"/>
    </visual>
    <collision>
      <geometry>
        <mesh filename="package://urdf_tutorial/meshes/prop_m_v1.STL"/>
      </geometry>
      <origin rpy="1.57075 0 0" xyz="0 0 0"/>
    </collision>
    <inertial>
    	<mass value="5"/>
    	<inertia ixx="0.4" ixy="0.0" ixz="0.0" iyy="0.4" iyz="0.0" izz="0.2"/>
    </inertial>
  </link>

    <joint name="prop_joint2" type="continuous">
    <parent link="base_link"/>
    <child link="prop2"/>
    <origin xyz="0.12713 -0.07122 -0.05281" rpy="0 0 0" />
    <axis xyz="0 1 0" />
  </joint>

  <link name="prop2">
    <visual>
      <geometry>
        <mesh filename="package://urdf_tutorial/meshes/prop_m_v1.STL"/>
      </geometry>
      <origin rpy="1.57075 0 0" xyz="0 0 0"/>
      <material name="blue"/>
    </visual>
    <collision>
      <geometry>
        <mesh filename="package://urdf_tutorial/meshes/prop_m_v1.STL"/>
      </geometry>
      <origin rpy="1.57075 0 0" xyz="0 0 0"/>
    </collision>
    <inertial>
    	<mass value="5"/>
    	<inertia ixx="0.4" ixy="0.0" ixz="0.0" iyy="0.4" iyz="0.0" izz="0.2"/>
    </inertial>
  </link>

  </robot>
